<?xml version="1.0" encoding="UTF-8"?>
<!-- Generated by org.testng.reporters.JUnitReportReporter -->
<testsuite hostname="MS-DT-0043" name="com.modular.framework.Functional_TestSuites.QuoteConsideredLatestTest" tests="6" failures="0" timestamp="19 May 2017 06:02:09 GMT" time="172.891" errors="1">
  <testcase name="fetchQuoteDetails" time="21.450" classname="com.modular.framework.Functional_TestSuites.QuoteConsideredLatestTest">
    <error type="java.lang.NullPointerException">
      <![CDATA[java.lang.NullPointerException
	at java.lang.String.contains(Unknown Source)
	at com.modular.framework.Functional_TestSuites.QuoteConsideredLatestTest.selectEnquiryId(QuoteConsideredLatestTest.java:478)
	at com.modular.framework.Functional_TestSuites.QuoteConsideredLatestTest.fetchQuoteDetails(QuoteConsideredLatestTest.java:81)
	at sun.reflect.NativeMethodAccessorImpl.invoke0(Native Method)
	at sun.reflect.NativeMethodAccessorImpl.invoke(Unknown Source)
	at sun.reflect.DelegatingMethodAccessorImpl.invoke(Unknown Source)
	at java.lang.reflect.Method.invoke(Unknown Source)
	at org.testng.internal.MethodInvocationHelper.invokeMethod(MethodInvocationHelper.java:86)
	at org.testng.internal.Invoker.invokeMethod(Invoker.java:646)
	at org.testng.internal.Invoker.invokeTestMethod(Invoker.java:823)
	at org.testng.internal.Invoker.invokeTestMethods(Invoker.java:1131)
	at org.testng.internal.TestMethodWorker.invokeTestMethods(TestMethodWorker.java:129)
	at org.testng.internal.TestMethodWorker.run(TestMethodWorker.java:112)
	at org.testng.TestRunner.privateRun(TestRunner.java:778)
	at org.testng.TestRunner.run(TestRunner.java:632)
	at org.testng.SuiteRunner.runTest(SuiteRunner.java:366)
	at org.testng.SuiteRunner.runSequentially(SuiteRunner.java:361)
	at org.testng.SuiteRunner.privateRun(SuiteRunner.java:319)
	at org.testng.SuiteRunner.run(SuiteRunner.java:268)
	at org.testng.SuiteRunnerWorker.runSuite(SuiteRunnerWorker.java:52)
	at org.testng.SuiteRunnerWorker.run(SuiteRunnerWorker.java:86)
	at org.testng.TestNG.runSuitesSequentially(TestNG.java:1225)
	at org.testng.TestNG.runSuitesLocally(TestNG.java:1150)
	at org.testng.TestNG.runSuites(TestNG.java:1075)
	at org.testng.TestNG.run(TestNG.java:1047)
	at org.testng.remote.AbstractRemoteTestNG.run(AbstractRemoteTestNG.java:126)
	at org.testng.remote.RemoteTestNG.initAndRun(RemoteTestNG.java:137)
	at org.testng.remote.RemoteTestNG.main(RemoteTestNG.java:58)
]]>
    </error>
  </testcase> <!-- fetchQuoteDetails -->
  <testcase name="fetchQuoteDetails" time="30.603" classname="com.modular.framework.Functional_TestSuites.QuoteConsideredLatestTest"/>
  <testcase name="fetchQuoteDetails" time="30.069" classname="com.modular.framework.Functional_TestSuites.QuoteConsideredLatestTest"/>
  <testcase name="fetchQuoteDetails" time="30.295" classname="com.modular.framework.Functional_TestSuites.QuoteConsideredLatestTest"/>
  <testcase name="fetchQuoteDetails" time="30.325" classname="com.modular.framework.Functional_TestSuites.QuoteConsideredLatestTest"/>
  <testcase name="fetchQuoteDetails" time="30.149" classname="com.modular.framework.Functional_TestSuites.QuoteConsideredLatestTest"/>
</testsuite> <!-- com.modular.framework.Functional_TestSuites.QuoteConsideredLatestTest -->
